<?xml version="1.0" ?>
<robot name="hmbot">

   <link name="base_link">
        <visual>
            <origin xyz=" 0 0 -0.02" rpy="0 0 0" />
            <geometry>
                <box size="0.4 0.3 0.04"/>
            </geometry>
            <material name="grey">
                <color rgba="0.8 0.8 0.8 1"/>
            </material>
        </visual>
    </link> 

    <joint name="left_wheel_joint" type="continuous">
        <origin xyz="0 0.15 -0.05" rpy="0 0 0"/>
        <parent link="base_link"/>
        <child link="left_wheel_link"/>
        <axis xyz="0 1 0"/>
    </joint>

    <link name="left_wheel_link">
        <visual>
            <origin xyz="0 0 0" rpy="1.5707 0 0" />
            <geometry>
                <cylinder radius="0.05" length = "0.025"/>
            </geometry>
            <material name="white">
                <color rgba="1 1 1 0.9"/>
            </material>
        </visual>
    </link>

    <joint name="right_wheel_joint" type="continuous">
        <origin xyz="0 -0.15 -0.05" rpy="0 0 0"/>
        <parent link="base_link"/>
        <child link="right_wheel_link"/>
        <axis xyz="0 1 0"/>
    </joint>

    <link name="right_wheel_link">
        <visual>
            <origin xyz="0 0 0" rpy="1.5707 0 0" />
            <geometry>
                <cylinder radius="0.05" length = "0.025"/>
            </geometry>
            <material name="white">
                <color rgba="1 1 1 0.9"/>
            </material>
        </visual>
    </link>

    <joint name="front_caster_joint" type="continuous">
        <origin xyz="0.12 0 -0.06" rpy="0 0 0"/>
        <parent link="base_link"/>
        <child link="front_caster_link"/>
        <axis xyz="0 1 0"/>
    </joint>

    <link name="front_caster_link">
        <visual>
            <origin xyz="0 0 0" rpy="0 0 0"/>
            <geometry>
                <sphere radius="0.03" />
            </geometry>
            <material name="black">
                <color rgba="0 0 0 0.95"/>
            </material>
        </visual>
    </link>

    <joint name="back_caster_joint" type="continuous">
        <origin xyz="-0.12 0 -0.06" rpy="0 0 0"/>
        <parent link="base_link"/>
        <child link="back_caster_link"/>
        <axis xyz="0 1 0"/>
    </joint>

    <link name="back_caster_link">
        <visual>
            <origin xyz="0 0 0" rpy="0 0 0"/>
            <geometry>
                <sphere radius="0.03" />
            </geometry>
            <material name="black">
                <color rgba="0 0 0 0.95"/>
            </material>
        </visual>
    </link>
	

    <joint name="support_leftup_joint" type="fixed">
        <origin xyz="-0.18 0.13 0.05" rpy="0 0 0"/>
        <parent link="base_link"/>
        <child link="support_leftup_link"/>
        <axis xyz="0 1 0"/>
    </joint>

    <link name="support_leftup_link">
        <visual>
            <origin xyz=" 0 0 0" rpy="0 0 0" />
            <geometry>
                <cylinder radius="0.01" length = "0.1"/>
            </geometry>
            <material name="yellow">
                <color rgba="1 0.4 0 1"/>
            </material>
        </visual>
    </link>

   <joint name="support_rightup_joint" type="fixed">
        <origin xyz="0.18 0.13 0.05" rpy="0 0 0"/>
        <parent link="base_link"/>
        <child link="support_rightup_link"/>
        <axis xyz="0 1 0"/>
    </joint>

    <link name="support_rightup_link">
        <visual>
            <origin xyz=" 0 0 0" rpy="0 0 0" />
            <geometry>
                <cylinder radius="0.01" length = "0.1"/>
            </geometry>
            <material name="yellow">
                <color rgba="1 0.4 0 1"/>
            </material>
        </visual>
    </link>

    <joint name="support_leftdown_joint" type="fixed">
        <origin xyz="-0.18 -0.13 0.05" rpy="0 0 0"/>
        <parent link="base_link"/>
        <child link="support_leftdown_link"/>
        <axis xyz="0 1 0"/>
    </joint>

    <link name="support_leftdown_link">
        <visual>
            <origin xyz=" 0 0 0" rpy="0 0 0" />
            <geometry>
                <cylinder radius="0.01" length = "0.1"/>
            </geometry>
            <material name="yellow">
                <color rgba="1 0.4 0 1"/>
            </material>
        </visual>
    </link>

    <joint name="support_rightdown_joint" type="fixed">
        <origin xyz="0.18 -0.13 0.05" rpy="0 0 0"/>
        <parent link="base_link"/>
        <child link="support_rightdown_link"/>
        <axis xyz="0 1 0"/>
    </joint>

    <link name="support_rightdown_link">
        <visual>
            <origin xyz=" 0 0 0" rpy="0 0 0" />
            <geometry>
                <cylinder radius="0.01" length = "0.1"/>
            </geometry>
            <material name="yellow">
                <color rgba="1 0.4 0 1"/>
            </material>
        </visual>
    </link>

    <joint name="support_middle_joint" type="fixed">
        <origin xyz="0 0 0.05" rpy="0 0 0"/>
        <parent link="base_link"/>
        <child link="support_middle_link"/>
        <axis xyz="0 1 0"/>
    </joint>

    <link name="support_middle_link">
        <visual>
            <origin xyz=" 0 0 0" rpy="0 0 0" />
            <geometry>
                <cylinder radius="0.01" length = "0.1"/>
            </geometry>
            <material name="yellow">
                <color rgba="1 0.4 0 1"/>
            </material>
        </visual>
    </link>

    <joint name="base_level_joint" type="fixed">
        <origin xyz="0 0 0.08" rpy="0 0 0"/>
        <parent link="support_middle_link"/>
        <child link="base_level_link"/>
        <axis xyz="0 1 0"/>
    </joint>

    <link name="base_level_link">
        <visual>
            <origin xyz=" 0 0 -0.02" rpy="0 0 0" />
            <geometry>
                <box size="0.4 0.3 0.04"/>
            </geometry>
            <material name="grey">
                <color rgba="0.8 0.8 0.8 1"/>
            </material>
        </visual>
    </link>

    <joint name="laser_joint" type="fixed">
        <origin xyz="-0.15 0 0.01" rpy="0 0 0"/>
        <parent link="base_level_link"/>
        <child link="laser_link"/>
        <axis xyz="0 1 0"/>
    </joint>

    <link name="laser_link">
        <visual>
            <origin xyz=" 0 0 0" rpy="0 0 0" />
            <geometry>
                <cylinder radius="0.04" length = "0.04"/>
            </geometry>
            <material name="yellow">
                <color rgba="1 0.4 0 1"/>
            </material>
        </visual>
    </link>

   <joint name="support_levelld_joint" type="fixed">
        <origin xyz="0.18 -0.13 0.01" rpy="0 0 0"/>
        <parent link="base_level_link"/>
        <child link="support_levelld_link"/>
        <axis xyz="0 1 0"/>
    </joint>

    <link name="support_levelld_link">
        <visual>
            <origin xyz=" 0 0 0" rpy="0 0 0" />
            <geometry>
                <cylinder radius="0.01" length = "0.1"/>
            </geometry>
            <material name="yellow">
                <color rgba="1 0.4 0 1"/>
            </material>
        </visual>
    </link>

    <joint name="support_levelrd_joint" type="fixed">
        <origin xyz="0.18 0.13 0.01" rpy="0 0 0"/>
        <parent link="base_level_link"/>
        <child link="support_levelrd_link"/>
        <axis xyz="0 1 0"/>
    </joint>

    <link name="support_levelrd_link">
        <visual>
            <origin xyz=" 0 0 0" rpy="0 0 0" />
            <geometry>
                <cylinder radius="0.01" length = "0.1"/>
            </geometry>
            <material name="yellow">
                <color rgba="1 0.4 0 1"/>
            </material>
        </visual>
    </link>
  
    <joint name="support_levellu_joint" type="fixed">
        <origin xyz="0 -0.13 0.01" rpy="0 0 0"/>
        <parent link="base_level_link"/>
        <child link="support_levellu_link"/>
        <axis xyz="0 1 0"/>
    </joint>

    <link name="support_levellu_link">
        <visual>
            <origin xyz=" 0 0 0" rpy="0 0 0" />
            <geometry>
                <cylinder radius="0.01" length = "0.1"/>
            </geometry>
            <material name="yellow">
                <color rgba="1 0.4 0 1"/>
            </material>
        </visual>
    </link>

    <joint name="support_levelru_joint" type="fixed">
        <origin xyz="0 0.13 0.01" rpy="0 0 0"/>
        <parent link="base_level_link"/>
        <child link="support_levelru_link"/>
        <axis xyz="0 1 0"/>
    </joint>

    <link name="support_levelru_link">
        <visual>
            <origin xyz=" 0 0 0" rpy="0 0 0" />
            <geometry>
                <cylinder radius="0.01" length = "0.1"/>
            </geometry>
            <material name="yellow">
                <color rgba="1 0.4 0 1"/>
            </material>
        </visual>
    </link>  
 
    <joint name="base_leveltop_joint" type="fixed">
        <origin xyz="-0.09 -0.13 0.08" rpy="0 0 0"/>
        <parent link="support_levelrd_link"/>
        <child link="base_leveltop_link"/>
        <axis xyz="0 1 0"/>
    </joint>

    <link name="base_leveltop_link">
        <visual>
            <origin xyz=" 0 0 -0.02" rpy="0 0 0" />
            <geometry>
                <box size="0.2 0.3 0.02"/>
            </geometry>
            <material name="grey">
                <color rgba="0.8 0.8 0.8 1"/>
            </material>
        </visual>
    </link>

    <joint name="kinect_joint" type="fixed">
        <origin xyz="0 0 0.01" rpy="0 0 0"/>
        <parent link="base_leveltop_link"/>
        <child link="kinect_link"/>
     </joint>

     <link name="kinect_link">
        <visual>
            <origin xyz="0 0 0" rpy="0 0 1.5708"/>
            <geometry>
                <mesh filename="package://hmbot_description/meshes/kinect.dae" />
            </geometry>
        </visual>
    </link>

   

</robot>
